Workbook

Sheet 00_README
B2: BRIDGEAPP: QUALIFYING SPRINT
B3: 14 days, Mon 24 Aug to Sun 6 Sep 2026. Purpose: establish the real cost per sale on both growth engines before committing the full budget.
B5: How this workbook is used
B6: Every morning | C6: The named owner fills yesterday's row in 05_Daily_Log. Yellow cells are the only cells anyone types into.
B7: Every Monday | C7: 10_KPIs is read at stand-up. Any KPI on its trigger is discussed before anything else.
B8: Day 14 (6 Sep) | C8: 11_Go_No_Go is completed. That sheet decides whether the full budget is released, held, or re-cut.
B9: Never | C9: Do not type over a black cell. Black cells are formulas and will stop calculating.
B11: Sheet guide
B12: 00_README | C12: This sheet.
B13: 01_Owners | C13: Named owner per sheet and per decision. Fill the Named Person column before day 1.
B14: 02_Baselines | C14: Real reported figures from Meta, Instagram, Facebook and TikTok. The only hard numbers the campaign holds.
B15: 03_Sprint_Drivers | C15: Every assumption in one place. Change a yellow cell here and the whole workbook recalculates.
B16: 04_Sprint_Plan | C16: The 14 days, day by day. GE tag, deliverable, owner, due, status.
B17: 05_Daily_Log | C17: The data entry sheet. Everything else in this workbook reads from it.
B18: 06_GE1_Paid_Media | C18: Paid media engine. Spend, clicks, signups, sales, cost per sale. Reads 05_Daily_Log.
B19: 07_GE2_School_Outreach | C19: School outreach engine. Visits, calls, signups captured, sales. Reads 05_Daily_Log.
B20: 08_School_Visits | C20: The visit schedule for these 14 days, and the result of each visit.
B21: 09_UTM_Register | C21: Every tagged link used in the sprint. A link that is not on this sheet does not get counted.
B22: 10_KPIs | C22: Live dashboard by engine. Current pulls from 05_Daily_Log. Target and Trigger are fixed.
B23: 11_Go_No_Go | C23: The day 14 decision gate, with the thresholds written before the sprint starts.
B25: Colour legend
B26: Yellow fill | C26: An input. Type here. These are the only cells that should ever be edited.
B27: Blue bold text | C27: A number that was typed in, not calculated. Change it in 03_Sprint_Drivers only.
B28: Black text | C28: A formula. Do not overwrite.
B29: Orange fill | C29: Blocked on someone outside this team. Named in the row.
B31: Source for all pre-filled targets and budget lines: BridgeApp Phase 2 Operating Workbook v4 (May 2026), sheets 02_Budget_Master, 03_Calendar_Phase2, 04_GE1_Tracker, 05_GE2_Tracker, 09_KPIs_By_GE.
B32: Source for the 40 000 by 30 Nov 2026 target and the 15 week pace: campaign brief, Blank Canvas.
B33: Sales in this sprint are counted from the Peach transaction export reconciled against the ledger. GA4 cannot attribute a sale until the purchase event is installed. See 03_Sprint_Drivers row 24.

Sheet 01_Owners
B2: OWNERS
B3: One name per sheet. Fill the yellow Named Person column before day 1. An unowned sheet does not get filled in.
B5: Sheet ownership
B6: Sheet / workstream | C6: Owner role | D6: Named person | E6: Cadence
B7: 03_Sprint_Drivers | C7: Campaign Lead | D7: TBC | E7: Weekly, Monday
B8: 04_Sprint_Plan | C8: Campaign Lead | D8: TBC | E8: Daily
B9: 05_Daily_Log (GE1 columns) | C9: Performance Marketer | D9: TBC | E9: Daily by 09:00
B10: 05_Daily_Log (GE2 columns) | C10: Schools Coordinator | D10: TBC | E10: Same day as visit
B11: 06_GE1_Paid_Media | C11: Performance Marketer | D11: TBC | E11: Daily
B12: 07_GE2_School_Outreach | C12: Schools Coordinator | D12: TBC | E12: Daily
B13: 08_School_Visits | C13: Schools Coordinator | D13: TBC | E13: Same day as visit
B14: 09_UTM_Register | C14: Performance Marketer | D14: TBC | E14: Before any link goes live
B15: 10_KPIs | C15: Campaign Lead | D15: TBC | E15: Weekly, Monday stand-up
B16: 11_Go_No_Go | C16: Campaign Lead | D16: TBC | E16: Once, day 14
B17: Peach reconciliation to ledger | C17: Campaign Lead | D17: TBC | E17: Daily by 09:00
... B19: Organic content in support of sprint | C19: Content Producer | D19: TBC | E19: Daily
B21: Decision authority for these 14 days
B22: Decision | C22: Approver | D22: Escalation | E22: Notes
B23: Move spend between GE1 and GE2 | C23: Campaign Lead | D23: MD | E23: Inside the sprint cap only
B24: Any spend above the sprint cap | C24: MD | D24: Founders | E24: Pre approval, in writing
B25: Pause a channel mid sprint | C25: Performance Marketer | D25: Campaign Lead | E25: Same day if cost per sale doubles target
B26: Add or drop a school visit | C26: Schools Coordinator | D26: Campaign Lead | E26: Log the reason in 08_School_Visits
B27: Publish a link without a UTM | C27: Not permitted | D27: Campaign Lead | E27: Untagged traffic cannot be counted
B28: Change a driver in 03_Sprint_Drivers | C28: Campaign Lead | D28: MD | E28: Note the date and reason in the row
B29: Day 14 go or no go | C29: MD | D29: Founders | E29: On the evidence in 11_Go_No_Go

Sheet 02_Baselines
B2: BASELINES: WHAT THE PLATFORMS ALREADY TELL US
B3: Real reported figures, not estimates. Every driver on 03_Sprint_Drivers that can be grounded in one of these is grounded in it.
B5: Paid: Meta boosted post, 29 July to 5 August 2026, 8 days
B6: Reported figure | C6: Value | E6: Source
B7: Spend | C7: 1617.57 | E7: Meta Ad insights, boosted Instagram post, screenshot 20 Aug 2026.
B8: Daily budget | C8: 232 | E8: Meta Ad insights, boosted Instagram post, screenshot 20 Aug 2026.
B9: Views | C9: 15979 | E9: Meta Ad insights, boosted Instagram post, screenshot 20 Aug 2026.
B10: Viewers reached | C10: 11034 | E10: Meta Ad insights, boosted Instagram post, screenshot 20 Aug 2026.
B11: Link clicks | C11: 491 | E11: Meta Ad insights, boosted Instagram post, screenshot 20 Aug 2026.
B12: Link click through rate | C12: 0.031 | E12: Meta Ad insights, boosted Instagram post, screenshot 20 Aug 2026.
B13: Cost per link click | C13: ='02_Baselines'!$C$7/'02_Baselines'!$C$11 | E13: Calculated from the two rows above. This is the only cost figure in the campaign that is real.
B14: Instagram profile visits | C14: 490 | E14: Meta Ad insights, boosted Instagram post, screenshot 20 Aug 2026.
B15: Cost per profile visit | C15: 3.3 | E15: Meta Ad insights, boosted Instagram post, screenshot 20 Aug 2026.
B16: Instagram follows | C16: 127 | E16: Meta Ad insights, boosted Instagram post, screenshot 20 Aug 2026.
B17: Post engagements | C17: 6595 | E17: Meta Ad insights, boosted Instagram post, screenshot 20 Aug 2026.
B18: Reactions | C18: 417 | E18: Meta Ad insights, boosted Instagram post, screenshot 20 Aug 2026.
B19: Comments | C19: 1 | E19: Meta Ad insights, boosted Instagram post, screenshot 20 Aug 2026.
B20: Shares | C20: 30 | E20: Meta Ad insights, boosted Instagram post, screenshot 20 Aug 2026.
B21: Saves | C21: 52 | E21: Meta Ad insights, boosted Instagram post, screenshot 20 Aug 2026.
B22: Reel plays | C22: 14730 | E22: Meta Ad insights, boosted Instagram post, screenshot 20 Aug 2026.
B23: ThruPlays | C23: 1757 | E23: Meta Ad insights, boosted Instagram post, screenshot 20 Aug 2026.
B24: Video length (seconds) | C24: 53 | E24: Meta Ad insights, boosted Instagram post, screenshot 20 Aug 2026.
B25: Average watch time (seconds) | C25: 7 | E25: Meta Ad insights, boosted Instagram post, screenshot 20 Aug 2026.
... B27: Hold rate | C27: 0.076 | E27: Meta Ad insights, boosted Instagram post, screenshot 20 Aug 2026.
B29: Paid: who it actually reached
B30: Reported figure | C30: Value | E30: Source
B31: Women | C31: 0.607 | E31: Meta Ad insights, boosted Instagram post, screenshot 20 Aug 2026.
B32: Men | C32: 0.384 | E32: Meta Ad insights, boosted Instagram post, screenshot 20 Aug 2026.
B33: Non binary | C33: 0.009 | E33: Meta Ad insights, boosted Instagram post, screenshot 20 Aug 2026.
B34: Largest age band | C34: 35 to 44 | E34: Meta reports bands as bars without figures. 35 to 44 is the longest bar, 25 to 34 second.
B35: Gauteng | C35: Largest | E35: Bar is full width, figure not shown in the export.
B36: KwaZulu Natal | C36: 1200 | E36: Meta Ad insights, boosted Instagram post, screenshot 20 Aug 2026.
B37: Western Cape | C37: 863 | E37: Meta Ad insights, boosted Instagram post, screenshot 20 Aug 2026.
B38: Limpopo | C38: 572 | E38: Meta Ad insights, boosted Instagram post, screenshot 20 Aug 2026.
B39: Eastern Cape | C39: 556 | E39: Meta Ad insights, boosted Instagram post, screenshot 20 Aug 2026.
B40: Mpumalanga | C40: 556 | E40: Meta Ad insights, boosted Instagram post, screenshot 20 Aug 2026.
B42: Organic: reel on Facebook and Instagram
B43: Reported figure | C43: Value | E43: Source
B44: Views, total | C44: 12677 | E44: Reel insights, screenshot 20 Aug 2026.
B45: Views, Instagram | C45: 11992 | E45: Reel insights, screenshot 20 Aug 2026.
...

Sheet 03_Sprint_Drivers
B2: SPRINT DRIVERS
B3: Every assumption in one cell. Yellow cells are set by a person. Everything else calculates. Cost per sale is derived here, never assumed.
B5: Sprint window
B6: Driver | C6: Value | E6: Source or note
B7: Sprint start | C7: 46258 | E7: Monday. First full week after the 21 Aug data pull.
B8: Sprint end | C8: 46271 | E8: Sunday. Two complete weeks.
B9: Days in sprint | C9: ='03_Sprint_Drivers'!$C$8-'03_Sprint_Drivers'!$C$7+1 | E9: Calculated.
B11: What is being risked, and what it has to prove
B12: Driver | C12: Value | E12: Source or note
B13: Sprint media cap, GE1 paid (R) | C13: 10000 | E13: Agreed 21 Aug: R5 000 a week across both weeks. Sits inside the R250 000 of paid media the v4 plan already carries rather than adding to it.
B14: Qualifying sales target | C14: 61 | E14: Agreed 21 Aug. What R10 000 returns if click to sale is 2%, which is the hypothesis being tested. Hitting it confirms 2% and tells exco R2m buys about 12 100 sales, not 40 000.
B15: Share of the target from GE1 paid | C15: 1 | E15: 100% this sprint. The 61 is what the paid budget buys. School outreach carries no media spend and is setting its first baseline, so it is measured rather than targeted.
B16: Share of the target from GE2 schools | C16: =1-'03_Sprint_Drivers'!$C$15 | E16: Calculated. Zero by design this sprint. GE2 sales are counted and reported, just not targeted.
B17: GE1 sales target | C17: =ROUND('03_Sprint_Drivers'!$C$14*'03_Sprint_Drivers'!$C$15,0) | E17: Calculated.
B18: GE2 sales target | C18: ='03_Sprint_Drivers'!$C$14-'03_Sprint_Drivers'!$C$17 | E18: Calculated. Remainder, so the two always sum to the target.
B19: Sales required per day | C19: =ROUND('03_Sprint_Drivers'!$C$14/'03_Sprint_Drivers'!$C$9,1) | E19: Calculated.
B21: What the real cost per click means for that target
B22: Driver | C22: Value | E22: Source or note
B23: Cost per link click | C23: ='02_Baselines'!$C$13 | E23: Real. From the July Meta boost on 02_Baselines. Not an estimate.
B24: Clicks the cap buys at that rate | C24: =ROUND('03_Sprint_Drivers'!$C$13/'03_Sprint_Drivers'!$C$23,0) | E24: Calculated.
B25: Click to sale rate GE1 must achieve | C25: =IFERROR('03_Sprint_Drivers'!$C$17/'03_Sprint_Drivers'!$C$24,0) | E25: Calculated. THE TEST. Nobody knows the real rate, because no click has ever been tied to a payment. For R2m to buy 40 000 this would have to reach 6.6% at today's cost per click.
B26: Cost per sale this implies, GE1 | C26: =IFERROR('03_Sprint_Drivers'!$C$13/'03_Sprint_Drivers'!$C$17,0) | E26: Calculated from the cap and the target, not assumed. v4 sheet 09 sets R85 as the cost per free signup target.
B28: What the cap buys at different click to sale rates
B29: If click to sale is | C29: Cost per sale becomes | D29: Sales the cap buys
B30: 0.005 | C30: ='03_Sprint_Drivers'!$C$23/B30 | D30: =ROUND('03_Sprint_Drivers'!$C$24*B30,0)
B31: 0.01 | C31: ='03_Sprint_Drivers'!$C$23/B31 | D31: =ROUND('03_Sprint_Drivers'!$C$24*B31,0)
B32: 0.02 | C32: ='03_Sprint_Drivers'!$C$23/B32 | D32: =ROUND('03_Sprint_Drivers'!$C$24*B32,0)
B33: 0.04 | C33: ='03_Sprint_Drivers'!$C$23/B33 | D33: =ROUND('03_Sprint_Drivers'!$C$24*B33,0)
B34: 0.08 | C34: ='03_Sprint_Drivers'!$C$23/B34 | D34: =ROUND('03_Sprint_Drivers'!$C$24*B34,0)
B35: Read this against the target above. It is the whole commercial question in five rows.
B37: Against the full campaign
B38: Driver | C38: Value | E38: Source or note
B39: Full campaign target | C39: 40000 | E39: Campaign brief. Paid transactions by 30 Nov 2026.
B40: Weeks from sprint start to deadline | C40: 15 | E40: 24 Aug to 30 Nov 2026.
B41: Required pace per week | C41: =ROUND('03_Sprint_Drivers'!$C$39/'03_Sprint_Drivers'!$C$40,0) | E41: Calculated.
B42: Required sales in a 14 day window | C42: ='03_Sprint_Drivers'!$C$41*2 | E42: Calculated. What full pace looks like over this sprint.
B43: This sprint as a share of full pace | C43: =IFERROR('03_Sprint_Drivers'!$C$14/'03_Sprint_Drivers'!$C$42,0) | E43: Calculated. How far the qualifying target sits below full pace.
B45: How a sale is counted in this sprint
B46: Primary source | C46: Peach transaction export, reconciled against the sales ledger daily by 09:00 by the Campaign Lead.
B47: Attribution to engine | C47: By the UTM on the link the buyer arrived through, registered in 09_UTM_Register. A sale with no UTM is logged as unattributed.
...

Sheet 04_Sprint_Plan
B2: SPRINT PLAN: 14 DAYS
B3: Every commitment in the window. GE3 rows are carried from the Phase 2 calendar; they consume team time but carry no sales target in this sprint.
B5: Mon 24 Aug to Sun 6 Sep 2026
B6: Day | C6: Date | D6: GE | E6: Deliverable | F6: Owner | G6: Due | H6: Status | I6: Source
B7: 1 | C7: 46258 | D7: ALL | E7: Sprint drivers locked and signed off | F7: Campaign Lead | G7: 24 Aug | H7: PLANNED | I7: Sprint
B8: 1 | D8: ALL | E8: Every role in 01_Owners has a named person | F8: Campaign Lead | G8: 24 Aug | H8: PLANNED | I8: Sprint
B9: 1 | D9: GE1 | E9: 09_UTM_Register complete. No link goes live untagged | F9: Performance Marketer | G9: 24 Aug | H9: PLANNED | I9: Sprint
B10: 1 | D10: ALL | E10: Baseline: closing Peach ledger count recorded in 05_Daily_Log | F10: Campaign Lead | G10: 24 Aug | H10: PLANNED | I10: Sprint
B11: 1 | D11: GE1 | E11: Paid buy live on Meta against the sprint cap | F11: Performance Marketer | G11: 24 Aug | H11: PLANNED | I11: Sprint
B12: 1 | D12: GE2 | E12: Week 1 visit schedule confirmed with each school | F12: Schools Coordinator | G12: 24 Aug | H12: PLANNED | I12: Sprint
B13: 1 | D13: ALL | E13: Escalation sent to Gradesmatch dev on the three blocked items | F13: Campaign Lead | G13: 24 Aug | H13: PLANNED | I13: Blocked: dev
B14: 2 | C14: 46259 | D14: GE1 | E14: First 24 hour read. Pull any creative below the CTR floor | F14: Performance Marketer | G14: 25 Aug | H14: PLANNED | I14: Sprint
B15: 2 | D15: GE2 | E15: School visits 1 and 2 | F15: Schools Coordinator | G15: 25 Aug | H15: PLANNED | I15: Sprint
B16: 2 | D16: GE1 | E16: FC 25K Push continues, paid and organic | F16: Performance Marketer | G16: Continuous | H16: PLANNED | I16: v4 Calendar
B17: 3 | C17: 46260 | D17: GE2 | E17: School visits 3 and 4 | F17: Schools Coordinator | G17: 26 Aug | H17: PLANNED | I17: Sprint
B18: 3 | D18: GE1 | E18: Creative variant set 2 live | F18: Designer | G18: 26 Aug | H18: PLANNED | I18: Sprint
B19: 3 | D19: GE3 | E19: BMW Golf Clinic invitee list sent | F19: Strategy Lead | G19: 26 Aug | H19: PLANNED | I19: v4 Calendar
B20: 4 | C20: 46261 | D20: GE1 | E20: UniApply matric urgency push live | F20: Performance Marketer | G20: 27 Aug | H20: PLANNED | I20: v4 Calendar
B21: 4 | D21: GE2 | E21: School visits 5 and 6 | F21: Schools Coordinator | G21: 27 Aug | H21: PLANNED | I21: Sprint
B22: 4 | D22: ALL | E22: Mid week reconciliation check against Peach | F22: Campaign Lead | G22: 27 Aug | H22: PLANNED | I22: Sprint
B23: 5 | C23: 46262 | D23: GE1 | E23: Influencer Wave 3, GP creator, content live | F23: Creator Manager | G23: 28 Aug | H23: PLANNED | I23: v4 Calendar
B24: 5 | D24: GE2 | E24: Week 1 visit results logged in 08_School_Visits | F24: Schools Coordinator | G24: 28 Aug | H24: PLANNED | I24: Sprint
B25: 5 | D25: ALL | E25: Week 1 working book updated | F25: Campaign Lead | G25: 28 Aug | H25: PLANNED | I25: Sprint
B26: 5 | D26: GE3 | E26: Podcast pilot episode format lock | F26: Content Producer | G26: 28 Aug | H26: PLANNED | I26: v4 Calendar
B27: 6 | C27: 46263 | D27: GE1 | E27: Weekend spend read. No new creative | F27: Performance Marketer | G27: 29 Aug | H27: PLANNED | I27: Sprint
B28: 6 | D28: GE1 | E28: Organic conversion post, both channels | F28: Content Producer | G28: 29 Aug | H28: PLANNED | I28: Sprint
B29: 7 | C29: 46264 | D29: GE1 | E29: Week 1 close. Cost per sale for week 1 computed | F29: Performance Marketer | G29: 30 Aug | H29: PLANNED | I29: Sprint
B30: 8 | C30: 46265 | D30: ALL | E30: Week 1 review at stand up. 10_KPIs read before anything else | F30: Campaign Lead | G30: 31 Aug | H30: PLANNED | I30: Sprint
B31: 8 | D31: GE1 | E31: Reallocate spend across channels, inside the cap | F31: Performance Marketer | G31: 31 Aug | H31: PLANNED | I31: Sprint
B32: 8 | D32: GE2 | E32: Week 2 visit schedule confirmed | F32: Schools Coordinator | G32: 31 Aug | H32: PLANNED | I32: Sprint
B33: 8 | D33: GE3 | E33: BMW and Porsche negotiation close, signature | F33: Strategy Lead | G33: 31 Aug | H33: PLANNED | I33: v4 Calendar
B34: 9 | C34: 46266 | D34: GE2 | E34: School visits 7 and 8 | F34: Schools Coordinator | G34: 1 Sep | H34: PLANNED | I34: Sprint
B35: 9 | D35: GE2 | E35: Conference follow up and MOU push begins | F35: Schools Coordinator | G35: 1 Sep | H35: PLANNED | I35: v4 Calendar
B36: 9 | D36: GE2 | E36: SAHISA Durban prep begins, conference 13 to 16 Sep | F36: Schools Coordinator | G36: 1 Sep | H36: PLANNED | I36: v4 Calendar
B37: 9 | D37: GE1 | E37: Creative variant set 3 live | F37: Designer | G37: 1 Sep | H37: PLANNED | I37: Sprint
B38: 10 | C38: 46267 | D38: GE2 | E38: School visits 9 and 10 | F38: Schools Coordinator | G38: 2 Sep | H38: PLANNED | I38: Sprint
B39: 10 | D39: GE1 | E39: Mid sprint cost per sale read against target | F39: Performance Marketer | G39: 2 Sep | H39: PLANNED | I39: Sprint
B40: 11 | C40: 46268 | D40: GE2 | E40: School visits 11 and 12 | F40: Schools Coordinator | G40: 3 Sep | H40: PLANNED | I40: Sprint
B41: 11 | D41: GE1 | E41: Pause any channel running above twice target cost per sale | F41: Performance Marketer | G41: 3 Sep | H41: PLANNED | I41: Sprint
B42: 12 | C42: 46269 | D42: ALL | E42: Week 2 working book updated | F42: Campaign Lead | G42: 4 Sep | H42: PLANNED | I42: Sprint
...

Sheet 05_Daily_Log
B2: DAILY LOG
B3: The only sheet anyone types numbers into. Filled every morning for the day before, by 09:00. Every other sheet reads from here.
B5: Type into the yellow cells only. Grey columns are calculated.
E6: GE1: PAID MEDIA | I6: GE2: SCHOOL OUTREACH | M6: CALCULATED
B7: Date | C7: Day | D7: Spend (R) | E7: Clicks | F7: Signups | G7: Sales | H7: Schools visited | I7: Calls | J7: Signups captured | K7: Sales | L7: Total sales | M7: Cumulative | N7: Target cum. | O7: Variance | P7: Note
B8: 46258 | C8: 1 | L8: =G8+K8 | M8: =SUM($L$8:L8) | N8: =ROUND('03_Sprint_Drivers'!$C$14/'03_Sprint_Drivers'!$C$9*C8,0) | O8: =M8-N8
B9: 46259 | C9: 2 | L9: =G9+K9 | M9: =SUM($L$8:L9) | N9: =ROUND('03_Sprint_Drivers'!$C$14/'03_Sprint_Drivers'!$C$9*C9,0) | O9: =M9-N9
B10: 46260 | C10: 3 | L10: =G10+K10 | M10: =SUM($L$8:L10) | N10: =ROUND('03_Sprint_Drivers'!$C$14/'03_Sprint_Drivers'!$C$9*C10,0) | O10: =M10-N10
B11: 46261 | C11: 4 | L11: =G11+K11 | M11: =SUM($L$8:L11) | N11: =ROUND('03_Sprint_Drivers'!$C$14/'03_Sprint_Drivers'!$C$9*C11,0) | O11: =M11-N11
B12: 46262 | C12: 5 | L12: =G12+K12 | M12: =SUM($L$8:L12) | N12: =ROUND('03_Sprint_Drivers'!$C$14/'03_Sprint_Drivers'!$C$9*C12,0) | O12: =M12-N12
B13: 46263 | C13: 6 | L13: =G13+K13 | M13: =SUM($L$8:L13) | N13: =ROUND('03_Sprint_Drivers'!$C$14/'03_Sprint_Drivers'!$C$9*C13,0) | O13: =M13-N13
B14: 46264 | C14: 7 | L14: =G14+K14 | M14: =SUM($L$8:L14) | N14: =ROUND('03_Sprint_Drivers'!$C$14/'03_Sprint_Drivers'!$C$9*C14,0) | O14: =M14-N14
B15: 46265 | C15: 8 | L15: =G15+K15 | M15: =SUM($L$8:L15) | N15: =ROUND('03_Sprint_Drivers'!$C$14/'03_Sprint_Drivers'!$C$9*C15,0) | O15: =M15-N15
B16: 46266 | C16: 9 | L16: =G16+K16 | M16: =SUM($L$8:L16) | N16: =ROUND('03_Sprint_Drivers'!$C$14/'03_Sprint_Drivers'!$C$9*C16,0) | O16: =M16-N16
B17: 46267 | C17: 10 | L17: =G17+K17 | M17: =SUM($L$8:L17) | N17: =ROUND('03_Sprint_Drivers'!$C$14/'03_Sprint_Drivers'!$C$9*C17,0) | O17: =M17-N17
B18: 46268 | C18: 11 | L18: =G18+K18 | M18: =SUM($L$8:L18) | N18: =ROUND('03_Sprint_Drivers'!$C$14/'03_Sprint_Drivers'!$C$9*C18,0) | O18: =M18-N18
B19: 46269 | C19: 12 | L19: =G19+K19 | M19: =SUM($L$8:L19) | N19: =ROUND('03_Sprint_Drivers'!$C$14/'03_Sprint_Drivers'!$C$9*C19,0) | O19: =M19-N19
... B21: 46271 | C21: 14 | L21: =G21+K21 | M21: =SUM($L$8:L21) | N21: =ROUND('03_Sprint_Drivers'!$C$14/'03_Sprint_Drivers'!$C$9*C21,0) | O21: =M21-N21
B22: TOTAL | D22: =SUM(D8:D21) | E22: =SUM(E8:E21) | F22: =SUM(F8:F21) | G22: =SUM(G8:G21) | H22: =SUM(H8:H21) | I22: =SUM(I8:I21) | J22: =SUM(J8:J21) | K22: =SUM(K8:K21) | L22: =SUM(L8:L21) | N22: ='03_Sprint_Drivers'!$C$14 | O22: =L22-N22
B24: EXAMPLE ROW, do not type over the log above. Delete this block once the team has filled day 1.
B25: Mon 24 Aug | C25: 1 | D25: R2 400 | E25: 310 | F25: 44 | G25: 6 | H25: 2 | I25: 9 | J25: 31 | K25: 3 | L25: 9 | M25: 9 | N25: 18 | O25: -9 | P25: Meta set A pulled at 14:00, CTR 0.6%
B27: Spend is what the platform reports as spent that day, not what was budgeted.
B28: Sales are taken from the reconciled Peach export, split by the UTM the buyer arrived through. A sale with no UTM goes in neither engine column and is noted.
B29: Signups captured (GE2) are parent sign ups taken at a visit, from the QR code or the paper sheet, entered the same day.
B30: Target cum. divides the qualifying target evenly across 14 days. It is a pace line, not a forecast.

Sheet 06_GE1_Paid_Media
B2: GE1: PAID MEDIA
B3: Owner: Performance Marketer. Every figure reads from 05_Daily_Log. Nothing on this sheet is typed except the channel split below.
B5: Sprint to date
B6: Metric | C6: Actual | D6: Target | E6: Note
B7: Spend | C7: =SUM('05_Daily_Log'!D8:D21) | D7: ='03_Sprint_Drivers'!$C$13 | E7: Sum of the log.
B8: Clicks | C8: =SUM('05_Daily_Log'!E8:E21) | E8: Sum of the log.
B9: Signups | C9: =SUM('05_Daily_Log'!F8:F21) | E9: Sum of the log.
B10: Sales | C10: =SUM('05_Daily_Log'!G8:G21) | D10: ='03_Sprint_Drivers'!$C$17 | E10: Sum of the log. Peach reconciled, UTM attributed.
B11: Cost per sale | C11: =IFERROR(SUM('05_Daily_Log'!D8:D21)/SUM('05_Daily_Log'!G8:G21),0) | D11: ='03_Sprint_Drivers'!$C$26 | E11: The number this sprint exists to establish.
B12: Cost per signup | C12: =IFERROR(SUM('05_Daily_Log'!D8:D21)/SUM('05_Daily_Log'!F8:F21),0) | D12: 110 | E12: v4 GE1 KPI target is R85, current R110.
B13: Click to signup rate | C13: =IFERROR(SUM('05_Daily_Log'!F8:F21)/SUM('05_Daily_Log'!E8:E21),0) | E13: Landing page performance.
B14: Signup to sale rate | C14: =IFERROR(SUM('05_Daily_Log'!G8:G21)/SUM('05_Daily_Log'!F8:F21),0) | D14: 0.04 | E14: v4 GE1 KPI target is 4%.
B15: Spend left in the cap | C15: ='03_Sprint_Drivers'!$C$13-SUM('05_Daily_Log'!D8:D21) | E15: Negative means the cap is breached. That needs MD approval.
B16: Share of GE1 target banked | C16: =IFERROR(SUM('05_Daily_Log'!G8:G21)/'03_Sprint_Drivers'!$C$17,0) | D16: 1 | E16: Against the GE1 split of the qualifying target.
B18: Channel split. Type into the yellow cells
B19: Channel | C19: Budget (R) | D19: Spend (R) | E19: Sales / cost per sale
B20: Meta, paid social
B21: Google, paid search
B22: LinkedIn, paid
B23: Boosted organic posts
B24: Influencer Wave 3, GP creator | C24: 50000
B25: Channel total | C25: =SUM(C20:C24) | D25: =SUM(D20:D24) | E25: =SUM(E20:E24)
B26: Column E is sales, not cost per sale. Cost per sale per channel is D divided by E and is read at the Monday call.
B28: Influencer Wave 3 budget R50 000 is the v4 Budget Master line for Aug 2026. Confirm how much of it falls inside these 14 days.

Sheet 07_GE2_School_Outreach
B2: GE2: SCHOOL OUTREACH
B3: Owner: Schools Coordinator. Reads from 05_Daily_Log and 08_School_Visits. This engine is measured on the same basis as paid media.
B5: Sprint to date
B6: Metric | C6: Actual | D6: Target | E6: Note
B7: Schools visited | C7: =SUM('05_Daily_Log'!H8:H21) | D7: 12 | E7: 6 per week is the visit target.
B8: Calls made | C8: =SUM('05_Daily_Log'!I8:I21) | D8: 38 | E8: 19 per week. Calls plus visits equals the v4 GE2 target of 25 per week.
B9: Calls plus visits | C9: =SUM('05_Daily_Log'!H8:H21)+SUM('05_Daily_Log'!I8:I21) | D9: 50 | E9: v4 GE2 KPI. Trigger is below 15 in a week.
B10: Signups captured | C10: =SUM('05_Daily_Log'!J8:J21) | E10: Parent sign ups taken at a visit, same day entry.
B11: Sales | C11: =SUM('05_Daily_Log'!K8:K21) | D11: ='03_Sprint_Drivers'!$C$18 | E11: Peach reconciled, attributed to a school tagged link.
B12: Signups per visit | C12: =IFERROR(SUM('05_Daily_Log'!J8:J21)/SUM('05_Daily_Log'!H8:H21),0) | E12: The number that tells you whether visits are worth the travel.
B13: Sales per visit | C13: =IFERROR(SUM('05_Daily_Log'!K8:K21)/SUM('05_Daily_Log'!H8:H21),0) | E13: The school engine equivalent of cost per sale.
B14: Signup to sale rate | C14: =IFERROR(SUM('05_Daily_Log'!K8:K21)/SUM('05_Daily_Log'!J8:J21),0) | E14: Compare against the paid engine on 05.
B15: Share of GE2 target banked | C15: =IFERROR(SUM('05_Daily_Log'!K8:K21)/'03_Sprint_Drivers'!$C$18,0) | D15: 1 | E15: Against the GE2 split of the qualifying target.
B17: Sprint cost of this engine. Type into the yellow cells
B18: Cost line | C18: Sprint cost (R) | E18: Source
B19: School activations Wave 2 | E19: v4 Budget Master, R19 000 for all of Aug 2026. Enter only the portion inside these 14 days.
B20: Information sessions support | E20: v4 Budget Master, R5 000 across Aug and Sep 2026. Enter the sprint portion.
B21: Travel and fuel | E21: Actual, from expense claims.
B22: Printed material and QR codes | E22: Actual.
B23: Total GE2 sprint cost | C23: =SUM(C19:C22)
B24: Cost per sale, school engine | C24: =IFERROR(C23/SUM('05_Daily_Log'!K8:K21),0) | D24: ='03_Sprint_Drivers'!$C$26 | E24: Directly comparable with the paid media cost per sale on 05. This comparison is the point of the sprint.

Sheet 08_School_Visits
B2: SCHOOL VISITS
B3: Owner: Schools Coordinator. Logged the same day as the visit. Week 1 is assigned from the six active Phase 2 pilots. Week 2 is assigned at the day 8 stand up.
B5: Week 1: Tue 25, Wed 26, Thu 27 August
B6: # | C6: School | D6: Region | E6: Date | F6: Owner | G6: Status | H6: Parents reached | I6: Signups captured | J6: UTM content tag | K6: Sales attributed | L6: Notes
B7: 1 | C7: Kingsmead | D7: KZN (Durban) | E7: 46259 | F7: TBC | G7: PLANNED | J7: school-kingsmead
B8: 2 | C8: St Albans | D8: EC (Port Elizabeth) | E8: 46259 | F8: TBC | G8: PLANNED | J8: school-st
B9: 3 | C9: Dainfern College | D9: GP (JHB North) | E9: 46260 | F9: TBC | G9: PLANNED | J9: school-dainfern
B10: 4 | C10: Umtata International | D10: EC (Mthatha) | E10: 46260 | F10: TBC | G10: PLANNED | J10: school-umtata
B11: 5 | C11: St Jude Private | D11: EC | E11: 46261 | F11: TBC | G11: PLANNED | J11: school-st
B12: 6 | C12: Christ The King International | D12: EC | E12: 46261 | F12: TBC | G12: PLANNED | J12: school-christ
B14: Week 2: Tue 1, Wed 2, Thu 3 September. Schools assigned at the day 8 stand up
B15: # | C15: School | D15: Region | E15: Date | F15: Owner | G15: Status | H15: Parents reached | I15: Signups captured | J15: UTM content tag | K15: Sales attributed | L15: Notes
B16: 7 | E16: 46266 | G16: PLANNED
B17: 8 | E17: 46266 | G17: PLANNED
B18: 9 | E18: 46267 | G18: PLANNED
B19: 10 | E19: 46267 | G19: PLANNED
B20: 11 | E20: 46268 | G20: PLANNED
B21: 12 | E21: 46268 | G21: PLANNED
B23: Reference: the Phase 2 pool is 6 active pilots (Kingsmead, St Albans, Dainfern College, Umtata International, St Jude Private, Christ The King International) plus 2 backups (Strategic High, Excelsior High). Source: v4 sheet 07_Pilot_Schools.
B24: Every visit carries a QR code whose link is registered in 09_UTM_Register with utm_content set to the tag in column J. A visit with no tag produces sales nobody can attribute to it.
B25: Signups captured here must equal the GE2 signups captured entered in 05_Daily_Log for the same date.

Sheet 09_UTM_Register
B2: UTM REGISTER
B3: Every link used in the sprint. A link that is not on this sheet cannot be attributed, so the sale it produces counts for nobody.
B5: Type into the yellow cells. Column H builds itself
B6: Purpose | C6: Source | D6: Medium | E6: Campaign | F6: Content | G6: Landing URL | H6: Tagged URL, copy this one | I6: GE | J6: Owner | K6: Live from
B7: Meta paid, parent audience | C7: meta | D7: paid-social | E7: qualifying-sprint | F7: meta-set-a | G7: https://bridgeapp.co.za/uniapply-parents | H7: =IF(OR(G7="",C7="",D7=""),"",G7&"?utm_source="&SUBSTITUTE(SUBSTITUTE(SUBSTITUTE(LOWER(TRIM(C7))," ","-"),"/","-"),"--","-")&"&utm_medium="&SUBSTITUTE(SUBSTITUTE(SUBSTITUTE(LOWER(TRIM(D7))," ","-"),"/","-"),"--","-")&IF(E7="","","&utm_campaign="&SUBSTITUTE(SUBSTITUTE(SUBSTITUTE(LOWER(TRIM(E7))," ","-"),"/","-"),"--","-"))&IF(F7="","","&utm_content="&SUBSTITUTE(SUBSTITUTE(SUBSTITUTE(LOWER(TRIM(F7))," ","-"),"/","-"),"--","-"))) | I7: GE1 | J7: TBC
B8: Meta paid, retargeting July leads | C8: meta | D8: paid-social | E8: qualifying-sprint | F8: meta-retarget | G8: https://bridgeapp.co.za/uniapply-parents | H8: =IF(OR(G8="",C8="",D8=""),"",G8&"?utm_source="&SUBSTITUTE(SUBSTITUTE(SUBSTITUTE(LOWER(TRIM(C8))," ","-"),"/","-"),"--","-")&"&utm_medium="&SUBSTITUTE(SUBSTITUTE(SUBSTITUTE(LOWER(TRIM(D8))," ","-"),"/","-"),"--","-")&IF(E8="","","&utm_campaign="&SUBSTITUTE(SUBSTITUTE(SUBSTITUTE(LOWER(TRIM(E8))," ","-"),"/","-"),"--","-"))&IF(F8="","","&utm_content="&SUBSTITUTE(SUBSTITUTE(SUBSTITUTE(LOWER(TRIM(F8))," ","-"),"/","-"),"--","-"))) | I8: GE1 | J8: TBC
B9: Google paid search, brand | C9: google | D9: paid-search | E9: qualifying-sprint | F9: brand | G9: https://bridgeapp.co.za/uniapply-parents | H9: =IF(OR(G9="",C9="",D9=""),"",G9&"?utm_source="&SUBSTITUTE(SUBSTITUTE(SUBSTITUTE(LOWER(TRIM(C9))," ","-"),"/","-"),"--","-")&"&utm_medium="&SUBSTITUTE(SUBSTITUTE(SUBSTITUTE(LOWER(TRIM(D9))," ","-"),"/","-"),"--","-")&IF(E9="","","&utm_campaign="&SUBSTITUTE(SUBSTITUTE(SUBSTITUTE(LOWER(TRIM(E9))," ","-"),"/","-"),"--","-"))&IF(F9="","","&utm_content="&SUBSTITUTE(SUBSTITUTE(SUBSTITUTE(LOWER(TRIM(F9))," ","-"),"/","-"),"--","-"))) | I9: GE1 | J9: TBC
B10: LinkedIn paid, school leaders | C10: linkedin | D10: paid-social | E10: qualifying-sprint | F10: school-leaders | G10: https://bridgeapp.co.za/uniapply-parents | H10: =IF(OR(G10="",C10="",D10=""),"",G10&"?utm_source="&SUBSTITUTE(SUBSTITUTE(SUBSTITUTE(LOWER(TRIM(C10))," ","-"),"/","-"),"--","-")&"&utm_medium="&SUBSTITUTE(SUBSTITUTE(SUBSTITUTE(LOWER(TRIM(D10))," ","-"),"/","-"),"--","-")&IF(E10="","","&utm_campaign="&SUBSTITUTE(SUBSTITUTE(SUBSTITUTE(LOWER(TRIM(E10))," ","-"),"/","-"),"--","-"))&IF(F10="","","&utm_content="&SUBSTITUTE(SUBSTITUTE(SUBSTITUTE(LOWER(TRIM(F10))," ","-"),"/","-"),"--","-"))) | I10: GE1 | J10: TBC
B11: Boosted organic, best of last week | C11: facebook | D11: boosted | E11: qualifying-sprint | F11: weekly-boost | G11: https://bridgeapp.co.za/uniapply-parents | H11: =IF(OR(G11="",C11="",D11=""),"",G11&"?utm_source="&SUBSTITUTE(SUBSTITUTE(SUBSTITUTE(LOWER(TRIM(C11))," ","-"),"/","-"),"--","-")&"&utm_medium="&SUBSTITUTE(SUBSTITUTE(SUBSTITUTE(LOWER(TRIM(D11))," ","-"),"/","-"),"--","-")&IF(E11="","","&utm_campaign="&SUBSTITUTE(SUBSTITUTE(SUBSTITUTE(LOWER(TRIM(E11))," ","-"),"/","-"),"--","-"))&IF(F11="","","&utm_content="&SUBSTITUTE(SUBSTITUTE(SUBSTITUTE(LOWER(TRIM(F11))," ","-"),"/","-"),"--","-"))) | I11: GE1 | J11: TBC
B12: Influencer Wave 3, GP creator | C12: influencer | D12: referral | E12: qualifying-sprint | F12: wave-3-gp | G12: https://bridgeapp.co.za/uniapply-parents | H12: =IF(OR(G12="",C12="",D12=""),"",G12&"?utm_source="&SUBSTITUTE(SUBSTITUTE(SUBSTITUTE(LOWER(TRIM(C12))," ","-"),"/","-"),"--","-")&"&utm_medium="&SUBSTITUTE(SUBSTITUTE(SUBSTITUTE(LOWER(TRIM(D12))," ","-"),"/","-"),"--","-")&IF(E12="","","&utm_campaign="&SUBSTITUTE(SUBSTITUTE(SUBSTITUTE(LOWER(TRIM(E12))," ","-"),"/","-"),"--","-"))&IF(F12="","","&utm_content="&SUBSTITUTE(SUBSTITUTE(SUBSTITUTE(LOWER(TRIM(F12))," ","-"),"/","-"),"--","-"))) | I12: GE1 | J12: TBC
B13: Instagram bio link | C13: instagram | D13: organic-social | E13: qualifying-sprint | F13: bio-link | G13: https://bridgeapp.co.za/uniapply-parents | H13: =IF(OR(G13="",C13="",D13=""),"",G13&"?utm_source="&SUBSTITUTE(SUBSTITUTE(SUBSTITUTE(LOWER(TRIM(C13))," ","-"),"/","-"),"--","-")&"&utm_medium="&SUBSTITUTE(SUBSTITUTE(SUBSTITUTE(LOWER(TRIM(D13))," ","-"),"/","-"),"--","-")&IF(E13="","","&utm_campaign="&SUBSTITUTE(SUBSTITUTE(SUBSTITUTE(LOWER(TRIM(E13))," ","-"),"/","-"),"--","-"))&IF(F13="","","&utm_content="&SUBSTITUTE(SUBSTITUTE(SUBSTITUTE(LOWER(TRIM(F13))," ","-"),"/","-"),"--","-"))) | I13: GE1 | J13: TBC
B14: WhatsApp concierge broadcast | C14: whatsapp | D14: message | E14: qualifying-sprint | F14: broadcast | G14: https://bridgeapp.co.za/uniapply-parents | H14: =IF(OR(G14="",C14="",D14=""),"",G14&"?utm_source="&SUBSTITUTE(SUBSTITUTE(SUBSTITUTE(LOWER(TRIM(C14))," ","-"),"/","-"),"--","-")&"&utm_medium="&SUBSTITUTE(SUBSTITUTE(SUBSTITUTE(LOWER(TRIM(D14))," ","-"),"/","-"),"--","-")&IF(E14="","","&utm_campaign="&SUBSTITUTE(SUBSTITUTE(SUBSTITUTE(LOWER(TRIM(E14))," ","-"),"/","-"),"--","-"))&IF(F14="","","&utm_content="&SUBSTITUTE(SUBSTITUTE(SUBSTITUTE(LOWER(TRIM(F14))," ","-"),"/","-"),"--","-"))) | I14: GE1 | J14: TBC
B15: Nurture emailer | C15: email | D15: email | E15: qualifying-sprint | F15: nurture-1 | G15: https://bridgeapp.co.za/uniapply-parents | H15: =IF(OR(G15="",C15="",D15=""),"",G15&"?utm_source="&SUBSTITUTE(SUBSTITUTE(SUBSTITUTE(LOWER(TRIM(C15))," ","-"),"/","-"),"--","-")&"&utm_medium="&SUBSTITUTE(SUBSTITUTE(SUBSTITUTE(LOWER(TRIM(D15))," ","-"),"/","-"),"--","-")&IF(E15="","","&utm_campaign="&SUBSTITUTE(SUBSTITUTE(SUBSTITUTE(LOWER(TRIM(E15))," ","-"),"/","-"),"--","-"))&IF(F15="","","&utm_content="&SUBSTITUTE(SUBSTITUTE(SUBSTITUTE(LOWER(TRIM(F15))," ","-"),"/","-"),"--","-"))) | I15: GE1 | J15: TBC
B16: School visit QR, generic | C16: school-visits | D16: qr | E16: qualifying-sprint | G16: https://bridgeapp.co.za/uniapply-parents | H16: =IF(OR(G16="",C16="",D16=""),"",G16&"?utm_source="&SUBSTITUTE(SUBSTITUTE(SUBSTITUTE(LOWER(TRIM(C16))," ","-"),"/","-"),"--","-")&"&utm_medium="&SUBSTITUTE(SUBSTITUTE(SUBSTITUTE(LOWER(TRIM(D16))," ","-"),"/","-"),"--","-")&IF(E16="","","&utm_campaign="&SUBSTITUTE(SUBSTITUTE(SUBSTITUTE(LOWER(TRIM(E16))," ","-"),"/","-"),"--","-"))&IF(F16="","","&utm_content="&SUBSTITUTE(SUBSTITUTE(SUBSTITUTE(LOWER(TRIM(F16))," ","-"),"/","-"),"--","-"))) | I16: GE2 | J16: TBC
B17: School visit QR, per school | C17: school-visits | D17: qr | E17: qualifying-sprint | F17: school-kingsmead | G17: https://bridgeapp.co.za/uniapply-parents | H17: =IF(OR(G17="",C17="",D17=""),"",G17&"?utm_source="&SUBSTITUTE(SUBSTITUTE(SUBSTITUTE(LOWER(TRIM(C17))," ","-"),"/","-"),"--","-")&"&utm_medium="&SUBSTITUTE(SUBSTITUTE(SUBSTITUTE(LOWER(TRIM(D17))," ","-"),"/","-"),"--","-")&IF(E17="","","&utm_campaign="&SUBSTITUTE(SUBSTITUTE(SUBSTITUTE(LOWER(TRIM(E17))," ","-"),"/","-"),"--","-"))&IF(F17="","","&utm_content="&SUBSTITUTE(SUBSTITUTE(SUBSTITUTE(LOWER(TRIM(F17))," ","-"),"/","-"),"--","-"))) | I17: GE2 | J17: TBC
B18: Exhibition and conference QR | C18: school-events | D18: qr | E18: qualifying-sprint | F18: sahisa-durban | G18: https://bridgeapp.co.za/uniapply-parents | H18: =IF(OR(G18="",C18="",D18=""),"",G18&"?utm_source="&SUBSTITUTE(SUBSTITUTE(SUBSTITUTE(LOWER(TRIM(C18))," ","-"),"/","-"),"--","-")&"&utm_medium="&SUBSTITUTE(SUBSTITUTE(SUBSTITUTE(LOWER(TRIM(D18))," ","-"),"/","-"),"--","-")&IF(E18="","","&utm_campaign="&SUBSTITUTE(SUBSTITUTE(SUBSTITUTE(LOWER(TRIM(E18))," ","-"),"/","-"),"--","-"))&IF(F18="","","&utm_content="&SUBSTITUTE(SUBSTITUTE(SUBSTITUTE(LOWER(TRIM(F18))," ","-"),"/","-"),"--","-"))) | I18: GE2 | J18: TBC
B19: Parent info session handout | C19: school-visits | D19: print | E19: qualifying-sprint | F19: info-session | G19: https://bridgeapp.co.za/uniapply-parents | H19: =IF(OR(G19="",C19="",D19=""),"",G19&"?utm_source="&SUBSTITUTE(SUBSTITUTE(SUBSTITUTE(LOWER(TRIM(C19))," ","-"),"/","-"),"--","-")&"&utm_medium="&SUBSTITUTE(SUBSTITUTE(SUBSTITUTE(LOWER(TRIM(D19))," ","-"),"/","-"),"--","-")&IF(E19="","","&utm_campaign="&SUBSTITUTE(SUBSTITUTE(SUBSTITUTE(LOWER(TRIM(E19))," ","-"),"/","-"),"--","-"))&IF(F19="","","&utm_content="&SUBSTITUTE(SUBSTITUTE(SUBSTITUTE(LOWER(TRIM(F19))," ","-"),"/","-"),"--","-"))) | I19: GE2 | J19: TBC
B21: Landing URL is pre-filled with the parent page path. If the page is not deployed by day 1, change column G to the live destination on every row before any spend starts.
B22: Source and medium are compulsory. Campaign and content are optional and the formula leaves them out when blank.
B23: Everything is forced to lower case with spaces turned into hyphens, because GA4 treats Meta and meta as two different sources.

Sheet 10_KPIs
B2: KPI DASHBOARD
B3: Current reads live from 05_Daily_Log. Target and Trigger are fixed before the sprint starts and are not edited during it. Read at every Monday stand up.
B5: GE1: Paid media. Owner: Performance Marketer
B6: KPI | C6: GE | D6: Cadence | E6: Owner | F6: Current | G6: Target | H6: Trigger | I6: Good when | J6: Status
B7: Cost per sale, blended paid | C7: GE1 | D7: W | E7: Performance Marketer | F7: ='06_GE1_Paid_Media'!$C$11 | G7: ='03_Sprint_Drivers'!$C$26 | H7: ='03_Sprint_Drivers'!$C$26*2 | I7: lower | J7: =IF(NOT(ISNUMBER(H7)),"MANUAL",IF(F7=0,"NO DATA",IF(F7>H7,"REVIEW","OK")))
B8: Sales banked, GE1 | C8: GE1 | D8: W | E8: Performance Marketer | F8: ='06_GE1_Paid_Media'!$C$10 | G8: ='03_Sprint_Drivers'!$C$17 | H8: =ROUND('03_Sprint_Drivers'!$C$17*0.5,0) | I8: higher | J8: =IF(NOT(ISNUMBER(H8)),"MANUAL",IF(F8<H8,"REVIEW","OK"))
B9: Cost per signup | C9: GE1 | D9: W | E9: Performance Marketer | F9: ='06_GE1_Paid_Media'!$C$12 | G9: 85 | H9: 120 | I9: lower | J9: =IF(NOT(ISNUMBER(H9)),"MANUAL",IF(F9=0,"NO DATA",IF(F9>H9,"REVIEW","OK")))
B10: Signup to sale rate | C10: GE1 | D10: W | E10: Performance Marketer | F10: ='06_GE1_Paid_Media'!$C$14 | G10: 0.04 | H10: 0.025 | I10: higher | J10: =IF(NOT(ISNUMBER(H10)),"MANUAL",IF(F10<H10,"REVIEW","OK"))
B11: Spend left in the cap | C11: GE1 | D11: W | E11: Performance Marketer | F11: ='06_GE1_Paid_Media'!$C$15 | G11: 0 | H11: 0 | I11: higher | J11: =IF(NOT(ISNUMBER(H11)),"MANUAL",IF(F11<H11,"REVIEW","OK"))
B13: GE2: School outreach. Owner: Schools Coordinator
B14: KPI | C14: GE | D14: Cadence | E14: Owner | F14: Current | G14: Target | H14: Trigger | I14: Good when | J14: Status
B15: Sales banked, GE2 | C15: GE2 | D15: W | E15: Schools Coordinator | F15: ='07_GE2_School_Outreach'!$C$11 | G15: ='03_Sprint_Drivers'!$C$18 | H15: =ROUND('03_Sprint_Drivers'!$C$18*0.5,0) | I15: higher | J15: =IF(NOT(ISNUMBER(H15)),"MANUAL",IF(F15<H15,"REVIEW","OK"))
B16: Cost per sale, school engine | C16: GE2 | D16: W | E16: Schools Coordinator | F16: ='07_GE2_School_Outreach'!$C$24 | G16: ='03_Sprint_Drivers'!$C$26 | H16: ='03_Sprint_Drivers'!$C$26*2 | I16: lower | J16: =IF(NOT(ISNUMBER(H16)),"MANUAL",IF(F16=0,"NO DATA",IF(F16>H16,"REVIEW","OK")))
B17: Schools visited | C17: GE2 | D17: W | E17: Schools Coordinator | F17: ='07_GE2_School_Outreach'!$C$7 | G17: 12 | H17: 8 | I17: higher | J17: =IF(NOT(ISNUMBER(H17)),"MANUAL",IF(F17<H17,"REVIEW","OK"))
B18: Calls plus visits | C18: GE2 | D18: W | E18: Schools Coordinator | F18: ='07_GE2_School_Outreach'!$C$9 | G18: 50 | H18: 30 | I18: higher | J18: =IF(NOT(ISNUMBER(H18)),"MANUAL",IF(F18<H18,"REVIEW","OK"))
B19: Signups captured | C19: GE2 | D19: W | E19: Schools Coordinator | F19: ='07_GE2_School_Outreach'!$C$10 | G19: Baseline | H19: Baseline | I19: higher | J19: =IF(NOT(ISNUMBER(H19)),"MANUAL",IF(F19<H19,"REVIEW","OK"))
B20: Signups per visit | C20: GE2 | D20: W | E20: Schools Coordinator | F20: ='07_GE2_School_Outreach'!$C$12 | G20: Baseline | H20: Baseline | I20: higher | J20: =IF(NOT(ISNUMBER(H20)),"MANUAL",IF(F20<H20,"REVIEW","OK"))
B22: Sprint discipline. Owner: Campaign Lead
B23: KPI | C23: GE | D23: Cadence | E23: Owner | F23: Current | G23: Target | H23: Trigger | I23: Good when | J23: Status
B24: Days logged in 05_Daily_Log | C24: ALL | D24: D | E24: Campaign Lead | F24: =COUNT('05_Daily_Log'!$D$8:$D$21) | G24: 14 | H24: 12 | I24: higher | J24: =IF(NOT(ISNUMBER(H24)),"MANUAL",IF(F24<H24,"REVIEW","OK"))
B25: Links in 09_UTM_Register that build a tagged URL | C25: ALL | D25: W | E25: Performance Marketer | F25: =COUNTIF('09_UTM_Register'!$H$7:$H$19,"?*") | G25: 13 | H25: 13 | I25: higher | J25: =IF(NOT(ISNUMBER(H25)),"MANUAL",IF(F25<H25,"REVIEW","OK"))
B26: Peach reconciled to ledger by 09:00 | C26: ALL | D26: D | E26: Campaign Lead | F26: Pass | G26: Pass | H26: Any miss | I26: manual | J26: MANUAL
B27: Visit logged the same day | C27: ALL | D27: D | E27: Schools Coordinator | F27: Pass | G27: Pass | H27: Any miss | I27: manual | J27: MANUAL
B28: Working book updated Friday | C28: ALL | D28: W | E28: Campaign Lead | F28: Pass | G28: Pass | H28: Any miss | I28: manual | J28: MANUAL
B30: Baseline means there is no honest number to set yet. These are read for four weeks and the target is set off real data.
B31: MANUAL in the Status column means the row is judged by a person, not by a comparison. Cost per signup R85 target and R120 trigger, and the 4% signup to sale target, are from v4 sheet 10_KPIs_By_GE.

Sheet 11_Go_No_Go
B2: DAY 14 GO OR NO GO
B3: Completed on Sun 6 Sep 2026 by the Campaign Lead, decided by the MD. The thresholds below are set before the sprint starts and are not moved afterwards.
B5: The seven tests
B6: Test | C6: Result | D6: Threshold | E6: Verdict | F6: Note
B7: 1. Qualifying sales achieved | C7: ='05_Daily_Log'!$L$22 | D7: ='03_Sprint_Drivers'!$C$14 | E7: =IF(NOT(ISNUMBER(C7)),"NO DATA",IF(C7>=D7,"PASS","FAIL")) | F7: Total banked across both engines.
B8: 2. Blended cost per sale at or under target | C8: =IFERROR(('05_Daily_Log'!$D$22+'07_GE2_School_Outreach'!$C$23)/'05_Daily_Log'!$L$22,0) | D8: ='03_Sprint_Drivers'!$C$26 | E8: =IF(NOT(ISNUMBER(C8)),"NO DATA",IF(C8=0,"NO DATA",IF(C8<=D8,"PASS","FAIL"))) | F8: Paid media spend plus school engine cost, divided by all sales.
B9: 3. Paid engine at or under twice target | C9: ='06_GE1_Paid_Media'!$C$11 | D9: ='03_Sprint_Drivers'!$C$26*2 | E9: =IF(NOT(ISNUMBER(C9)),"NO DATA",IF(C9=0,"NO DATA",IF(C9<=D9,"PASS","FAIL"))) | F9: A paid engine above this is not scalable at the current creative.
B10: 4. School engine at or under twice target | C10: ='07_GE2_School_Outreach'!$C$24 | D10: ='03_Sprint_Drivers'!$C$26*2 | E10: =IF(NOT(ISNUMBER(C10)),"NO DATA",IF(C10=0,"NO DATA",IF(C10<=D10,"PASS","FAIL"))) | F10: Same test, applied to visits.
B11: 5. At least one engine at or under target | C11: =IF(OR(AND(ISNUMBER('06_GE1_Paid_Media'!$C$11),'06_GE1_Paid_Media'!$C$11<='03_Sprint_Drivers'!$C$26,'06_GE1_Paid_Media'!$C$11>0),AND(ISNUMBER('07_GE2_School_Outreach'!$C$24),'07_GE2_School_Outreach'!$C$24<='03_Sprint_Drivers'!$C$26,'07_GE2_School_Outreach'!$C$24>0)),1,0) | D11: 1 | E11: =IF(NOT(ISNUMBER(C11)),"NO DATA",IF(C11>=D11,"PASS","FAIL")) | F11: One working engine is enough to justify releasing budget into it.
B12: 6. Paid spend stayed inside the cap | C12: ='05_Daily_Log'!$D$22 | D12: ='03_Sprint_Drivers'!$C$13 | E12: =IF(NOT(ISNUMBER(C12)),"NO DATA",IF(C12=0,"NO DATA",IF(C12<=D12,"PASS","FAIL"))) | F12: A breach needs MD sign off recorded below.
B13: 7. Days logged | C13: =COUNT('05_Daily_Log'!$D$8:$D$21) | D13: 14 | E13: =IF(NOT(ISNUMBER(C13)),"NO DATA",IF(C13>=D13,"PASS","FAIL")) | F13: A sprint that was not logged did not measure anything, whatever the sales say.
B15: Tests passed | C15: =COUNTIF(E7:E13,"PASS") | D15: 7 | F15: NO DATA means the test had nothing to judge. Before the sprint runs, most tests read NO DATA. That is correct.
B16: Tests still reading NO DATA | C16: =COUNTIF(E7:E13,"NO DATA") | F16: Must be zero on day 14. A test with no data is a measurement failure, not a neutral result.
B18: What the result costs to scale
B19: Measure | C19: Value | F19: Note
B20: Sales still needed after this sprint | C20: =('03_Sprint_Drivers'!$C$39-'05_Daily_Log'!$L$22) | F20: Against the 40 000 target.
B21: Cost to buy them at the blended rate achieved | C21: =('03_Sprint_Drivers'!$C$39-'05_Daily_Log'!$L$22)*IFERROR(('05_Daily_Log'!$D$22+'07_GE2_School_Outreach'!$C$23)/'05_Daily_Log'!$L$22,0) | F21: This is the number the MD is actually deciding on.
B22: Cost to buy them at the target rate | C22: =('03_Sprint_Drivers'!$C$39-'05_Daily_Log'!$L$22)*'03_Sprint_Drivers'!$C$26 | F22: What the plan assumed.
B23: Difference | C23: =('03_Sprint_Drivers'!$C$39-'05_Daily_Log'!$L$22)*IFERROR(('05_Daily_Log'!$D$22+'07_GE2_School_Outreach'!$C$23)/'05_Daily_Log'!$L$22,0)-('03_Sprint_Drivers'!$C$39-'05_Daily_Log'!$L$22)*'03_Sprint_Drivers'!$C$26 | F23: Positive means the campaign costs more than planned.
B24: Weeks left after this sprint | C24: ='03_Sprint_Drivers'!$C$40-2 | F24: From 7 Sep to 30 Nov 2026.
B25: Sales per week required from here | C25: =IFERROR(ROUND(('03_Sprint_Drivers'!$C$39-'05_Daily_Log'!$L$22)/('03_Sprint_Drivers'!$C$40-2),0),0) | F25: Compare against what the sprint actually produced in two weeks.
B27: The decision
B28: Decision | F28: RELEASE FULL BUDGET / RELEASE INTO ONE ENGINE ONLY / HOLD AND RE-TEST / RE-CUT THE TARGET
B29: Reason | F29: One or two sentences. What the evidence showed.
B30: Budget released (R) | F30: Only if the decision is a release.
B31: Decided by
B32: Date
B33: Cap breach approved by | F33: Leave blank if test 6 passed.
